Workbook

Sheet Cover
B2: EA Take-Private: LBO Analysis
B3: Prepared by Alessandro Radice · Educational project, not investment advice
B6: Question | C6: Could a financial sponsor pay $210 per share for EA, and what return does the price imply?
B7: Inputs | C7: Financials, deal terms, the six debt tranches, base rates, scenario drivers and the scenario switch (C5)
B8: Sources & Uses | C8: Equity purchase, refinancing and fees vs new debt, balance-sheet cash and sponsor equity
B9: Operating Model | C9: Net bookings, adjusted EBITDA with cost savings, cash compensation, capex, taxes, free cash flow
B10: Debt Schedule | C10: Tranche by tranche: interest, mandatory amortisation, cash sweep, leverage and coverage
B11: Returns | C11: Exit value, sponsor IRR and MoM, maximum price at the target IRR, exit multiple needed at $210
B12: Sensitivity | C12: IRR by entry price and exit multiple, for the active scenario
B13: Colour code | C13: Blue = hard-coded input · Black = formula · Green = link to another sheet

Sheet Inputs
B2: Inputs
B3: $ millions unless stated · FY = fiscal year ending 31 March
B5: Active scenario (1 = Downside, 2 = Base, 3 = Upside) | C5: 2 | D5: =CHOOSE($C$5,"Downside","Base","Upside") -> Base
B8: Historical financials | C8: FY2025 | D8: FY2026
B9: Net revenue | C9: 7463 | D9: 7531
B10: Net bookings | C10: 7355 | D10: 8026
B11: Operating income (GAAP) | C11: 1520 | D11: 1162
B12: Depreciation & amortisation | C12: 356 | D12: 323
B13: Stock-based compensation | C13: 642 | D13: 656
B14: Capital expenditure | C14: 221 | D14: 230
B15: Adj. EBITDA (bookings basis) | C15: =C11+(C10-C9)+C12+C13 -> 2410 | D15: =D11+(D10-D9)+D12+D13 -> 2636 | I15: Operating income + change in deferred net revenue + D&A + SBC
B16: Adj. EBITDA margin on bookings | C16: =C15/C10 -> 0.32766825 | D16: =D15/D10 -> 0.32843259
B18: Deal terms and balance sheet
B19: Offer price per share ($) | C19: 210 | I19: All-cash merger consideration
B20: Premium to unaffected price | C20: 0.25 | I20: Reported 25%
B21: Shares outstanding (m) | C21: 250.75148 | I21: 10-K cover, 6 May 2026
B22: Cash and short-term investments, 31 Mar 2026 | C22: 2980 | I22: FY2026 earnings release
B23: Existing senior notes, refinanced | C23: 1485 | I23: Tendered or defeased at closing
B24: Minimum cash kept in the business | C24: 1000 | I24: Assumption
B25: Financing fees, % of new debt | C25: 0.015 | I25: Assumption
B26: OID on term loan B | C26: 0.015 | I26: Issued at 98.5
B27: Advisory and other costs, % of equity value | C27: 0.005 | I27: Assumption
B28: EBITDA marketed to lenders | C28: 3400 | I28: Incl. ~$400m savings and ~$300m addbacks
B29: SOFR | C29: 0.0375 | I29: Assumption
B30: Euribor | C30: 0.0225 | I30: Assumption
B31: Unaffected price ($) | C31: =Inputs!$C$19/(1+Inputs!$C$20) -> 168
B33: Debt package at closing (4 Aug 2026) | C33: Amount | D33: Floating? | E33: Spread/coupon | F33: All-in rate | G33: Amort. %/yr | H33: Prepayable?
B34: Term Loan A | C34: 3250 | D34: Yes | E34: 0.0175 | F34: =IF(D34="Yes",Inputs!$C$29,0)+E34 -> 0.055 | G34: 0.05 | H34: Yes | I34: Spread assumed (not disclosed); 5% amortisation assumed
B35: Term Loan B (USD) | C35: 6125 | D35: Yes | E35: 0.035 | F35: =IF(D35="Yes",Inputs!$C$29,0)+E35 -> 0.0725 | G35: 0.01 | H35: Yes | I35: Closing 8-K / syndication press
B36: Term Loan B (EUR €1,725m) | C36: 2000 | D36: Yes | E36: 0.035 | F36: =IF(D36="Yes",Inputs!$C$30,0)+E36 -> 0.0575 | G36: 0.01 | H36: Yes | I36: Closing 8-K / syndication press
B37: Senior secured notes 2033 (USD) | C37: 2875 | D37: No | E37: 0.0725 | F37: =IF(D37="Yes",0,0)+E37 -> 0.0725 | G37: 0 | H37: No | I37: Closing 8-K / syndication press
B38: Senior secured notes 2033 (EUR €1,080m) | C38: 1252.1739 | D38: No | E38: 0.0625 | F38: =IF(D38="Yes",0,0)+E38 -> 0.0625 | G38: 0 | H38: No | I38: Closing 8-K / syndication press
B39: Senior unsecured notes 2034 | C39: 2500 | D39: No | E39: 0.0875 | F39: =IF(D39="Yes",0,0)+E39 -> 0.0875 | G39: 0 | H39: No | I39: Closing 8-K / syndication press
B40: Total new debt | C40: =SUM(C34:C39) -> 18002.174
B41: Term loan B total | C41: =C35+C36 -> 8125
B43: Scenario drivers | C43: Downside | D43: Base | E43: Upside | F43: ► Live
B44: Net bookings growth per year | C44: 0.02 | D44: 0.05 | E44: 0.08 | F44: =CHOOSE(Inputs!$C$5,C44,D44,E44) -> 0.05
B45: Run-rate cost savings (50% in FY2027) | C45: 200 | D45: 400 | E45: 700 | F45: =CHOOSE(Inputs!$C$5,C45,D45,E45) -> 400
B46: Exit EV / adj. EBITDA | C46: 14 | D46: 16 | E46: 19 | F46: =CHOOSE(Inputs!$C$5,C46,D46,E46) -> 16
B48: Common assumptions
...

Sheet Sources & Uses
B2: Sources & uses at closing
B3: $ millions unless stated · FY = fiscal year ending 31 March
B6: Uses | C6: $m | D6: % total
B7: Purchase of equity | C7: =Inputs!$C$21*Inputs!$C$19 -> 52657.812 | D7: =C7/$C$12 -> 0.9609439
B8: Refinance existing senior notes | C8: =Inputs!$C$23 -> 1485 | D8: =C8/$C$12 -> 0.027099525
B9: Financing fees | C9: =Inputs!$C$40*Inputs!$C$25 -> 270.03261 | D9: =C9/$C$12 -> 0.0049277814
B10: OID on term loan B | C10: =Inputs!$C$41*Inputs!$C$26 -> 121.875 | D10: =C10/$C$12 -> 0.0022240772
B11: Advisory and other costs | C11: =C7*Inputs!$C$27 -> 263.28906 | D11: =C11/$C$12 -> 0.0048047195
B12: Total uses | C12: =SUM(C7:C11) -> 54798.008
B14: Sources | C14: $m | D14: % total
B15: New debt | C15: =Inputs!$C$40 -> 18002.174 | D15: =C15/$C$18 -> 0.32851876
B16: EA balance-sheet cash | C16: =Inputs!$C$22-Inputs!$C$24 -> 1980 | D16: =C16/$C$18 -> 0.0361327
B17: Sponsor equity (residual) | C17: =C12-C15-C16 -> 34815.834 | D17: =C17/$C$18 -> 0.63534854
B18: Total sources | C18: =SUM(C15:C17) -> 54798.008
B19: Check: sources − uses | C19: =ROUND(C18-C12,6) -> 0
B21: Entry valuation
B22: Entry EV (equity + old notes − cash) | C22: =C7+Inputs!$C$23-Inputs!$C$22 -> 51162.812
B23: EV / FY2026 adj. EBITDA | C23: =C22/Inputs!$D$15 -> 19.409261
B24: EV / marketing EBITDA | C24: =C22/Inputs!$C$28 -> 15.047886
B25: Gross leverage: new debt / FY2026 adj. EBITDA | C25: =Inputs!$C$40/Inputs!$D$15 -> 6.8293528
B26: Gross leverage on marketing EBITDA | C26: =Inputs!$C$40/Inputs!$C$28 -> 5.294757
B27: Equity cushion (sponsor equity / total sources) | C27: =C17/C18 -> 0.63534854
B28: Unaffected price ($) | C28: =Inputs!$C$31 -> 168

Sheet Operating Model
B2: Operating model (active scenario)
B3: $ millions unless stated · FY = fiscal year ending 31 March
B4: ="Scenario: "&Inputs!$D$5 -> Scenario: Base
C6: FY2026A | D6: FY2027E | E6: FY2028E | F6: FY2029E | G6: FY2030E | H6: FY2031E
B7: Net bookings | C7: =Inputs!$D$10 -> 8026 | D7: =C7*(1+Inputs!$F$44) -> 8427.3 | E7: =D7*(1+Inputs!$F$44) -> 8848.665 | F7: =E7*(1+Inputs!$F$44) -> 9291.0982 | G7: =F7*(1+Inputs!$F$44) -> 9755.6532 | H7: =G7*(1+Inputs!$F$44) -> 10243.436
B8: Growth | D8: =D7/C7-1 -> 0.05 | E8: =E7/D7-1 -> 0.05 | F8: =F7/E7-1 -> 0.05 | G8: =G7/F7-1 -> 0.05 | H8: =H7/G7-1 -> 0.05
B9: Adj. EBITDA before savings | D9: =D7*Inputs!$D$16 -> 2767.8 | E9: =E7*Inputs!$D$16 -> 2906.19 | F9: =F7*Inputs!$D$16 -> 3051.4995 | G9: =G7*Inputs!$D$16 -> 3204.0745 | H9: =H7*Inputs!$D$16 -> 3364.2782
B10: Cost savings | D10: =Inputs!$F$45*0.5 -> 200 | E10: =Inputs!$F$45*1 -> 400 | F10: =Inputs!$F$45*1 -> 400 | G10: =Inputs!$F$45*1 -> 400 | H10: =Inputs!$F$45*1 -> 400
B11: Adj. EBITDA | C11: =Inputs!$D$15 -> 2636 | D11: =D9+D10 -> 2967.8 | E11: =E9+E10 -> 3306.19 | F11: =F9+F10 -> 3451.4995 | G11: =G9+G10 -> 3604.0745 | H11: =H9+H10 -> 3764.2782
B12: Margin on bookings | C12: =C11/C7 -> 0.32843259 | D12: =D11/D7 -> 0.35216499 | E12: =E11/E7 -> 0.37363715 | F12: =F11/F7 -> 0.37148456 | G12: =G11/G7 -> 0.36943446 | H12: =H11/H7 -> 0.36748199
B13: (–) Cash compensation replacing SBC | D13: =-D7*Inputs!$C$51*Inputs!$C$52 -> -344.4 | E13: =-E7*Inputs!$C$51*Inputs!$C$52 -> -361.62 | F13: =-F7*Inputs!$C$51*Inputs!$C$52 -> -379.701 | G13: =-G7*Inputs!$C$51*Inputs!$C$52 -> -398.68605 | H13: =-H7*Inputs!$C$51*Inputs!$C$52 -> -418.62035
B14: (–) D&A | D14: =-D7*Inputs!$C$49 -> -339.15 | E14: =-E7*Inputs!$C$49 -> -356.1075 | F14: =-F7*Inputs!$C$49 -> -373.91287 | G14: =-G7*Inputs!$C$49 -> -392.60852 | H14: =-H7*Inputs!$C$49 -> -412.23894
B15: (–) Cash interest | D15: =-'Debt Schedule'!D$54 -> -1243.2609 | E15: =-'Debt Schedule'!E$54 -> -1191.5373 | F15: =-'Debt Schedule'!F$54 -> -1124.0797 | G15: =-'Debt Schedule'!G$54 -> -1048.6547 | H15: =-'Debt Schedule'!H$54 -> -940.01025
B16: EBT (tax basis) | D16: =D11+D13+D14+D15 -> 1040.9891 | E16: =E11+E13+E14+E15 -> 1396.9252 | F16: =F11+F13+F14+F15 -> 1573.8059 | G16: =G11+G13+G14+G15 -> 1764.1252 | H16: =H11+H13+H14+H15 -> 1993.4087
B17: (–) Cash taxes | D17: =-MAX(D16,0)*Inputs!$C$53 -> -218.60772 | E17: =-MAX(E16,0)*Inputs!$C$53 -> -293.3543 | F17: =-MAX(F16,0)*Inputs!$C$53 -> -330.49924 | G17: =-MAX(G16,0)*Inputs!$C$53 -> -370.46629 | H17: =-MAX(H16,0)*Inputs!$C$53 -> -418.61582
B18: (–) Capex | D18: =-D7*Inputs!$C$50 -> -241.5 | E18: =-E7*Inputs!$C$50 -> -253.575 | F18: =-F7*Inputs!$C$50 -> -266.25375 | G18: =-G7*Inputs!$C$50 -> -279.56644 | H18: =-H7*Inputs!$C$50 -> -293.54476
B19: Free cash flow after interest | D19: =D11+D13+D15+D17+D18 -> 920.03141 | E19: =E11+E13+E15+E17+E18 -> 1206.1034 | F19: =F11+F13+F15+F17+F18 -> 1350.9658 | G19: =G11+G13+G15+G17+G18 -> 1506.701 | H19: =H11+H13+H15+H17+H18 -> 1693.487

Sheet Debt Schedule
B2: Debt schedule (active scenario)
B3: $ millions unless stated · FY = fiscal year ending 31 March
C6: Closing | D6: FY2027E | E6: FY2028E | F6: FY2029E | G6: FY2030E | H6: FY2031E
B7: Term Loan A
B8: Opening balance | D8: =C11 -> 3250 | E8: =D11 -> 2411.2186 | F8: =E11 -> 1286.3652 | G8: =F11 -> 16.649349 | H8: =G11 -> 0
B9: Mandatory amortisation | D9: =-MIN(Inputs!$C$34*Inputs!$G$34,D8) -> -162.5 | E9: =-MIN(Inputs!$C$34*Inputs!$G$34,E8) -> -162.5 | F9: =-MIN(Inputs!$C$34*Inputs!$G$34,F8) -> -162.5 | G9: =-MIN(Inputs!$C$34*Inputs!$G$34,G8) -> -16.649349 | H9: =-MIN(Inputs!$C$34*Inputs!$G$34,H8) -> 0
B10: Cash sweep | D10: =-MIN(D50,D8+D9) -> -676.28141 | E10: =-MIN(E50,E8+E9) -> -962.35343 | F10: =-MIN(F50,F8+F9) -> -1107.2158 | G10: =-MIN(G50,G8+G9) -> 0 | H10: =-MIN(H50,H8+H9) -> 0
B11: Closing balance | C11: =Inputs!$C$34 -> 3250 | D11: =D8+D9+D10 -> 2411.2186 | E11: =E8+E9+E10 -> 1286.3652 | F11: =F8+F9+F10 -> 16.649349 | G11: =G8+G9+G10 -> 0 | H11: =H8+H9+H10 -> 0
B12: Interest (on opening) | D12: =D8*Inputs!$F$34 -> 178.75 | E12: =E8*Inputs!$F$34 -> 132.61702 | F12: =F8*Inputs!$F$34 -> 70.750083 | G12: =G8*Inputs!$F$34 -> 0.91571421 | H12: =H8*Inputs!$F$34 -> 0
B14: Term Loan B (USD)
B15: Opening balance | D15: =C18 -> 6125 | E15: =D18 -> 6063.75 | F15: =E18 -> 6002.5 | G15: =F18 -> 5941.25 | H15: =G18 -> 4471.1984
B16: Mandatory amortisation | D16: =-MIN(Inputs!$C$35*Inputs!$G$35,D15) -> -61.25 | E16: =-MIN(Inputs!$C$35*Inputs!$G$35,E15) -> -61.25 | F16: =-MIN(Inputs!$C$35*Inputs!$G$35,F15) -> -61.25 | G16: =-MIN(Inputs!$C$35*Inputs!$G$35,G15) -> -61.25 | H16: =-MIN(Inputs!$C$35*Inputs!$G$35,H15) -> -61.25
B17: Cash sweep | D17: =-MIN(D50+D10,D15+D16) -> 0 | E17: =-MIN(E50+E10,E15+E16) -> 0 | F17: =-MIN(F50+F10,F15+F16) -> 0 | G17: =-MIN(G50+G10,G15+G16) -> -1408.8016 | H17: =-MIN(H50+H10,H15+H16) -> -1612.237
B18: Closing balance | C18: =Inputs!$C$35 -> 6125 | D18: =D15+D16+D17 -> 6063.75 | E18: =E15+E16+E17 -> 6002.5 | F18: =F15+F16+F17 -> 5941.25 | G18: =G15+G16+G17 -> 4471.1984 | H18: =H15+H16+H17 -> 2797.7113
B19: Interest (on opening) | D19: =D15*Inputs!$F$35 -> 444.0625 | E19: =E15*Inputs!$F$35 -> 439.62187 | F19: =F15*Inputs!$F$35 -> 435.18125 | G19: =G15*Inputs!$F$35 -> 430.74063 | H19: =H15*Inputs!$F$35 -> 324.16188
B21: Term Loan B (EUR €1,725m)
B22: Opening balance | D22: =C25 -> 2000 | E22: =D25 -> 1980 | F22: =E25 -> 1960 | G22: =F25 -> 1940 | H22: =G25 -> 1920
B23: Mandatory amortisation | D23: =-MIN(Inputs!$C$36*Inputs!$G$36,D22) -> -20 | E23: =-MIN(Inputs!$C$36*Inputs!$G$36,E22) -> -20 | F23: =-MIN(Inputs!$C$36*Inputs!$G$36,F22) -> -20 | G23: =-MIN(Inputs!$C$36*Inputs!$G$36,G22) -> -20 | H23: =-MIN(Inputs!$C$36*Inputs!$G$36,H22) -> -20
B24: Cash sweep | D24: =-MIN(D50+D10+D17,D22+D23) -> 0 | E24: =-MIN(E50+E10+E17,E22+E23) -> 0 | F24: =-MIN(F50+F10+F17,F22+F23) -> 0 | G24: =-MIN(G50+G10+G17,G22+G23) -> 0 | H24: =-MIN(H50+H10+H17,H22+H23) -> 0
B25: Closing balance | C25: =Inputs!$C$36 -> 2000 | D25: =D22+D23+D24 -> 1980 | E25: =E22+E23+E24 -> 1960 | F25: =F22+F23+F24 -> 1940 | G25: =G22+G23+G24 -> 1920 | H25: =H22+H23+H24 -> 1900
B26: Interest (on opening) | D26: =D22*Inputs!$F$36 -> 115 | E26: =E22*Inputs!$F$36 -> 113.85 | F26: =F22*Inputs!$F$36 -> 112.7 | G26: =G22*Inputs!$F$36 -> 111.55 | H26: =H22*Inputs!$F$36 -> 110.4
B28: Senior secured notes 2033 (USD)
B29: Opening balance | D29: =C32 -> 2875 | E29: =D32 -> 2875 | F29: =E32 -> 2875 | G29: =F32 -> 2875 | H29: =G32 -> 2875
B30: Mandatory amortisation | D30: =-MIN(Inputs!$C$37*Inputs!$G$37,D29) -> 0 | E30: =-MIN(Inputs!$C$37*Inputs!$G$37,E29) -> 0 | F30: =-MIN(Inputs!$C$37*Inputs!$G$37,F29) -> 0 | G30: =-MIN(Inputs!$C$37*Inputs!$G$37,G29) -> 0 | H30: =-MIN(Inputs!$C$37*Inputs!$G$37,H29) -> 0
B31: Cash sweep | D31: 0 | E31: 0 | F31: 0 | G31: 0 | H31: 0
B32: Closing balance | C32: =Inputs!$C$37 -> 2875 | D32: =D29+D30+D31 -> 2875 | E32: =E29+E30+E31 -> 2875 | F32: =F29+F30+F31 -> 2875 | G32: =G29+G30+G31 -> 2875 | H32: =H29+H30+H31 -> 2875
B33: Interest (on opening) | D33: =D29*Inputs!$F$37 -> 208.4375 | E33: =E29*Inputs!$F$37 -> 208.4375 | F33: =F29*Inputs!$F$37 -> 208.4375 | G33: =G29*Inputs!$F$37 -> 208.4375 | H33: =H29*Inputs!$F$37 -> 208.4375
B35: Senior secured notes 2033 (EUR €1,080m)
B36: Opening balance | D36: =C39 -> 1252.1739 | E36: =D39 -> 1252.1739 | F36: =E39 -> 1252.1739 | G36: =F39 -> 1252.1739 | H36: =G39 -> 1252.1739
B37: Mandatory amortisation | D37: =-MIN(Inputs!$C$38*Inputs!$G$38,D36) -> 0 | E37: =-MIN(Inputs!$C$38*Inputs!$G$38,E36) -> 0 | F37: =-MIN(Inputs!$C$38*Inputs!$G$38,F36) -> 0 | G37: =-MIN(Inputs!$C$38*Inputs!$G$38,G36) -> 0 | H37: =-MIN(Inputs!$C$38*Inputs!$G$38,H36) -> 0
B38: Cash sweep | D38: 0 | E38: 0 | F38: 0 | G38: 0 | H38: 0
B39: Closing balance | C39: =Inputs!$C$38 -> 1252.1739 | D39: =D36+D37+D38 -> 1252.1739 | E39: =E36+E37+E38 -> 1252.1739 | F39: =F36+F37+F38 -> 1252.1739 | G39: =G36+G37+G38 -> 1252.1739 | H39: =H36+H37+H38 -> 1252.1739
B40: Interest (on opening) | D40: =D36*Inputs!$F$38 -> 78.26087 | E40: =E36*Inputs!$F$38 -> 78.26087 | F40: =F36*Inputs!$F$38 -> 78.26087 | G40: =G36*Inputs!$F$38 -> 78.26087 | H40: =H36*Inputs!$F$38 -> 78.26087
B42: Senior unsecured notes 2034
B43: Opening balance | D43: =C46 -> 2500 | E43: =D46 -> 2500 | F43: =E46 -> 2500 | G43: =F46 -> 2500 | H43: =G46 -> 2500
B44: Mandatory amortisation | D44: =-MIN(Inputs!$C$39*Inputs!$G$39,D43) -> 0 | E44: =-MIN(Inputs!$C$39*Inputs!$G$39,E43) -> 0 | F44: =-MIN(Inputs!$C$39*Inputs!$G$39,F43) -> 0 | G44: =-MIN(Inputs!$C$39*Inputs!$G$39,G43) -> 0 | H44: =-MIN(Inputs!$C$39*Inputs!$G$39,H43) -> 0
B45: Cash sweep | D45: 0 | E45: 0 | F45: 0 | G45: 0 | H45: 0
B46: Closing balance | C46: =Inputs!$C$39 -> 2500 | D46: =D43+D44+D45 -> 2500 | E46: =E43+E44+E45 -> 2500 | F46: =F43+F44+F45 -> 2500 | G46: =G43+G44+G45 -> 2500 | H46: =H43+H44+H45 -> 2500
B47: Interest (on opening) | D47: =D43*Inputs!$F$39 -> 218.75 | E47: =E43*Inputs!$F$39 -> 218.75 | F47: =F43*Inputs!$F$39 -> 218.75 | G47: =G43*Inputs!$F$39 -> 218.75 | H47: =H43*Inputs!$F$39 -> 218.75
B49: Total mandatory amortisation | D49: =D9+D16+D23+D30+D37+D44 -> -243.75 | E49: =E9+E16+E23+E30+E37+E44 -> -243.75 | F49: =F9+F16+F23+F30+F37+F44 -> -243.75 | G49: =G9+G16+G23+G30+G37+G44 -> -97.899349 | H49: =H9+H16+H23+H30+H37+H44 -> -81.25
...

Sheet Returns
B2: Returns and ability to pay (active scenario)
B3: $ millions unless stated · FY = fiscal year ending 31 March
B4: ="Scenario: "&Inputs!$D$5 -> Scenario: Base
B6: Exit adj. EBITDA (FY2031) | C6: ='Operating Model'!H11 -> 3764.2782
B7: Exit multiple | C7: =Inputs!$F$46 -> 16
B8: Exit enterprise value | C8: =C6*C7 -> 60228.451
B9: (–) Net debt at exit | C9: =-'Debt Schedule'!H55 -> -10324.885
B10: Exit equity value | C10: =C8+C9 -> 49903.566
B11: Sponsor equity invested | C11: ='Sources & Uses'!$C$17 -> 34815.834 | D11: PIF rollover counted as invested at $210
B12: Holding period (years) | C12: 5 | D12: Five full fiscal years FY2027-FY2031 (close Aug 2026)
B13: MoM | C13: =C10/C11 -> 1.4333583
B14: IRR | C14: =C13^(1/C12)-1 -> 0.074659679
B15: Equity for the target IRR | C15: =C10/(1+Inputs!$C$55)^C12 -> 20055.124
B16: Maximum price per share at the target IRR ($) | C16: =(C15-Inputs!$C$23-Inputs!$C$40*Inputs!$C$25-Inputs!$C$41*Inputs!$C$26+Inputs!$C$40+Inputs!$C$22-Inputs!$C$24)/(Inputs!$C$21*(1+Inputs!$C$27)) -> 151.42697
B17: vs offer price | C17: =C16/Inputs!$C$19-1 -> -0.27891919
B18: vs unaffected price | C18: =C16/Inputs!$C$31-1 -> -0.098648986
B19: Exit multiple needed for the target IRR at the offer price | C19: =(C11*(1+Inputs!$C$55)^C12-C9)/C6 -> 25.757348 | D19: C9 is negative net debt
B20: Debt repaid over the hold | C20: =Inputs!$C$40-'Debt Schedule'!H53 -> 6677.2887

Sheet Sensitivity
B2: Sponsor IRR: entry price (rows) × exit multiple (columns)
B3: Active scenario · debt package fixed at $18bn, so the price changes only the equity cheque
B6: Price per share ↓ / exit multiple → | C6: 12 | D6: 14 | E6: 16 | F6: 18 | G6: 20 | H6: 22
B7: 150 | C7: =((Returns!$C$6*C$6+Returns!$C$9)/(($B7*Inputs!$C$21)*(1+Inputs!$C$27)+Inputs!$C$23+Inputs!$C$40*Inputs!$C$25+Inputs!$C$41*Inputs!$C$26-Inputs!$C$40-(Inputs!$C$22-Inputs!$C$24)))^(1/Returns!$C$12)-1 -> 0.12087769 | D7: =((Returns!$C$6*D$6+Returns!$C$9)/(($B7*Inputs!$C$21)*(1+Inputs!$C$27)+Inputs!$C$23+Inputs!$C$40*Inputs!$C$25+Inputs!$C$41*Inputs!$C$26-Inputs!$C$40-(Inputs!$C$22-Inputs!$C$24)))^(1/Returns!$C$12)-1 -> 0.16559714 | E7: =((Returns!$C$6*E$6+Returns!$C$9)/(($B7*Inputs!$C$21)*(1+Inputs!$C$27)+Inputs!$C$23+Inputs!$C$40*Inputs!$C$25+Inputs!$C$41*Inputs!$C$26-Inputs!$C$40-(Inputs!$C$22-Inputs!$C$24)))^(1/Returns!$C$12)-1 -> 0.2043503 | F7: =((Returns!$C$6*F$6+Returns!$C$9)/(($B7*Inputs!$C$21)*(1+Inputs!$C$27)+Inputs!$C$23+Inputs!$C$40*Inputs!$C$25+Inputs!$C$41*Inputs!$C$26-Inputs!$C$40-(Inputs!$C$22-Inputs!$C$24)))^(1/Returns!$C$12)-1 -> 0.23867532 | G7: =((Returns!$C$6*G$6+Returns!$C$9)/(($B7*Inputs!$C$21)*(1+Inputs!$C$27)+Inputs!$C$23+Inputs!$C$40*Inputs!$C$25+Inputs!$C$41*Inputs!$C$26-Inputs!$C$40-(Inputs!$C$22-Inputs!$C$24)))^(1/Returns!$C$12)-1 -> 0.26956991 | H7: =((Returns!$C$6*H$6+Returns!$C$9)/(($B7*Inputs!$C$21)*(1+Inputs!$C$27)+Inputs!$C$23+Inputs!$C$40*Inputs!$C$25+Inputs!$C$41*Inputs!$C$26-Inputs!$C$40-(Inputs!$C$22-Inputs!$C$24)))^(1/Returns!$C$12)-1 -> 0.29772064
B8: 168 | C8: =((Returns!$C$6*C$6+Returns!$C$9)/(($B8*Inputs!$C$21)*(1+Inputs!$C$27)+Inputs!$C$23+Inputs!$C$40*Inputs!$C$25+Inputs!$C$41*Inputs!$C$26-Inputs!$C$40-(Inputs!$C$22-Inputs!$C$24)))^(1/Returns!$C$12)-1 -> 0.075363389 | D8: =((Returns!$C$6*D$6+Returns!$C$9)/(($B8*Inputs!$C$21)*(1+Inputs!$C$27)+Inputs!$C$23+Inputs!$C$40*Inputs!$C$25+Inputs!$C$41*Inputs!$C$26-Inputs!$C$40-(Inputs!$C$22-Inputs!$C$24)))^(1/Returns!$C$12)-1 -> 0.11826696 | E8: =((Returns!$C$6*E$6+Returns!$C$9)/(($B8*Inputs!$C$21)*(1+Inputs!$C$27)+Inputs!$C$23+Inputs!$C$40*Inputs!$C$25+Inputs!$C$41*Inputs!$C$26-Inputs!$C$40-(Inputs!$C$22-Inputs!$C$24)))^(1/Returns!$C$12)-1 -> 0.15544651 | F8: =((Returns!$C$6*F$6+Returns!$C$9)/(($B8*Inputs!$C$21)*(1+Inputs!$C$27)+Inputs!$C$23+Inputs!$C$40*Inputs!$C$25+Inputs!$C$41*Inputs!$C$26-Inputs!$C$40-(Inputs!$C$22-Inputs!$C$24)))^(1/Returns!$C$12)-1 -> 0.18837773 | G8: =((Returns!$C$6*G$6+Returns!$C$9)/(($B8*Inputs!$C$21)*(1+Inputs!$C$27)+Inputs!$C$23+Inputs!$C$40*Inputs!$C$25+Inputs!$C$41*Inputs!$C$26-Inputs!$C$40-(Inputs!$C$22-Inputs!$C$24)))^(1/Returns!$C$12)-1 -> 0.21801782 | H8: =((Returns!$C$6*H$6+Returns!$C$9)/(($B8*Inputs!$C$21)*(1+Inputs!$C$27)+Inputs!$C$23+Inputs!$C$40*Inputs!$C$25+Inputs!$C$41*Inputs!$C$26-Inputs!$C$40-(Inputs!$C$22-Inputs!$C$24)))^(1/Returns!$C$12)-1 -> 0.24502546
B9: 180 | C9: =((Returns!$C$6*C$6+Returns!$C$9)/(($B9*Inputs!$C$21)*(1+Inputs!$C$27)+Inputs!$C$23+Inputs!$C$40*Inputs!$C$25+Inputs!$C$41*Inputs!$C$26-Inputs!$C$40-(Inputs!$C$22-Inputs!$C$24)))^(1/Returns!$C$12)-1 -> 0.050365191 | D9: =((Returns!$C$6*D$6+Returns!$C$9)/(($B9*Inputs!$C$21)*(1+Inputs!$C$27)+Inputs!$C$23+Inputs!$C$40*Inputs!$C$25+Inputs!$C$41*Inputs!$C$26-Inputs!$C$40-(Inputs!$C$22-Inputs!$C$24)))^(1/Returns!$C$12)-1 -> 0.092271411 | E9: =((Returns!$C$6*E$6+Returns!$C$9)/(($B9*Inputs!$C$21)*(1+Inputs!$C$27)+Inputs!$C$23+Inputs!$C$40*Inputs!$C$25+Inputs!$C$41*Inputs!$C$26-Inputs!$C$40-(Inputs!$C$22-Inputs!$C$24)))^(1/Returns!$C$12)-1 -> 0.12858668 | F9: =((Returns!$C$6*F$6+Returns!$C$9)/(($B9*Inputs!$C$21)*(1+Inputs!$C$27)+Inputs!$C$23+Inputs!$C$40*Inputs!$C$25+Inputs!$C$41*Inputs!$C$26-Inputs!$C$40-(Inputs!$C$22-Inputs!$C$24)))^(1/Returns!$C$12)-1 -> 0.16075237 | G9: =((Returns!$C$6*G$6+Returns!$C$9)/(($B9*Inputs!$C$21)*(1+Inputs!$C$27)+Inputs!$C$23+Inputs!$C$40*Inputs!$C$25+Inputs!$C$41*Inputs!$C$26-Inputs!$C$40-(Inputs!$C$22-Inputs!$C$24)))^(1/Returns!$C$12)-1 -> 0.18970343 | H9: =((Returns!$C$6*H$6+Returns!$C$9)/(($B9*Inputs!$C$21)*(1+Inputs!$C$27)+Inputs!$C$23+Inputs!$C$40*Inputs!$C$25+Inputs!$C$41*Inputs!$C$26-Inputs!$C$40-(Inputs!$C$22-Inputs!$C$24)))^(1/Returns!$C$12)-1 -> 0.21608325
B10: 195 | C10: =((Returns!$C$6*C$6+Returns!$C$9)/(($B10*Inputs!$C$21)*(1+Inputs!$C$27)+Inputs!$C$23+Inputs!$C$40*Inputs!$C$25+Inputs!$C$41*Inputs!$C$26-Inputs!$C$40-(Inputs!$C$22-Inputs!$C$24)))^(1/Returns!$C$12)-1 -> 0.02343261 | D10: =((Returns!$C$6*D$6+Returns!$C$9)/(($B10*Inputs!$C$21)*(1+Inputs!$C$27)+Inputs!$C$23+Inputs!$C$40*Inputs!$C$25+Inputs!$C$41*Inputs!$C$26-Inputs!$C$40-(Inputs!$C$22-Inputs!$C$24)))^(1/Returns!$C$12)-1 -> 0.064264306 | E10: =((Returns!$C$6*E$6+Returns!$C$9)/(($B10*Inputs!$C$21)*(1+Inputs!$C$27)+Inputs!$C$23+Inputs!$C$40*Inputs!$C$25+Inputs!$C$41*Inputs!$C$26-Inputs!$C$40-(Inputs!$C$22-Inputs!$C$24)))^(1/Returns!$C$12)-1 -> 0.099648411 | F10: =((Returns!$C$6*F$6+Returns!$C$9)/(($B10*Inputs!$C$21)*(1+Inputs!$C$27)+Inputs!$C$23+Inputs!$C$40*Inputs!$C$25+Inputs!$C$41*Inputs!$C$26-Inputs!$C$40-(Inputs!$C$22-Inputs!$C$24)))^(1/Returns!$C$12)-1 -> 0.13098933 | G10: =((Returns!$C$6*G$6+Returns!$C$9)/(($B10*Inputs!$C$21)*(1+Inputs!$C$27)+Inputs!$C$23+Inputs!$C$40*Inputs!$C$25+Inputs!$C$41*Inputs!$C$26-Inputs!$C$40-(Inputs!$C$22-Inputs!$C$24)))^(1/Returns!$C$12)-1 -> 0.15919806 | H10: =((Returns!$C$6*H$6+Returns!$C$9)/(($B10*Inputs!$C$21)*(1+Inputs!$C$27)+Inputs!$C$23+Inputs!$C$40*Inputs!$C$25+Inputs!$C$41*Inputs!$C$26-Inputs!$C$40-(Inputs!$C$22-Inputs!$C$24)))^(1/Returns!$C$12)-1 -> 0.18490147
B11: 210 | C11: =((Returns!$C$6*C$6+Returns!$C$9)/(($B11*Inputs!$C$21)*(1+Inputs!$C$27)+Inputs!$C$23+Inputs!$C$40*Inputs!$C$25+Inputs!$C$41*Inputs!$C$26-Inputs!$C$40-(Inputs!$C$22-Inputs!$C$24)))^(1/Returns!$C$12)-1 -> 0.00017582787 | D11: =((Returns!$C$6*D$6+Returns!$C$9)/(($B11*Inputs!$C$21)*(1+Inputs!$C$27)+Inputs!$C$23+Inputs!$C$40*Inputs!$C$25+Inputs!$C$41*Inputs!$C$26-Inputs!$C$40-(Inputs!$C$22-Inputs!$C$24)))^(1/Returns!$C$12)-1 -> 0.040079653 | E11: =((Returns!$C$6*E$6+Returns!$C$9)/(($B11*Inputs!$C$21)*(1+Inputs!$C$27)+Inputs!$C$23+Inputs!$C$40*Inputs!$C$25+Inputs!$C$41*Inputs!$C$26-Inputs!$C$40-(Inputs!$C$22-Inputs!$C$24)))^(1/Returns!$C$12)-1 -> 0.074659679 | F11: =((Returns!$C$6*F$6+Returns!$C$9)/(($B11*Inputs!$C$21)*(1+Inputs!$C$27)+Inputs!$C$23+Inputs!$C$40*Inputs!$C$25+Inputs!$C$41*Inputs!$C$26-Inputs!$C$40-(Inputs!$C$22-Inputs!$C$24)))^(1/Returns!$C$12)-1 -> 0.1052884 | G11: =((Returns!$C$6*G$6+Returns!$C$9)/(($B11*Inputs!$C$21)*(1+Inputs!$C$27)+Inputs!$C$23+Inputs!$C$40*Inputs!$C$25+Inputs!$C$41*Inputs!$C$26-Inputs!$C$40-(Inputs!$C$22-Inputs!$C$24)))^(1/Returns!$C$12)-1 -> 0.1328561 | H11: =((Returns!$C$6*H$6+Returns!$C$9)/(($B11*Inputs!$C$21)*(1+Inputs!$C$27)+Inputs!$C$23+Inputs!$C$40*Inputs!$C$25+Inputs!$C$41*Inputs!$C$26-Inputs!$C$40-(Inputs!$C$22-Inputs!$C$24)))^(1/Returns!$C$12)-1 -> 0.15797542
B12: 225 | C12: =((Returns!$C$6*C$6+Returns!$C$9)/(($B12*Inputs!$C$21)*(1+Inputs!$C$27)+Inputs!$C$23+Inputs!$C$40*Inputs!$C$25+Inputs!$C$41*Inputs!$C$26-Inputs!$C$40-(Inputs!$C$22-Inputs!$C$24)))^(1/Returns!$C$12)-1 -> -0.020231546 | D12: =((Returns!$C$6*D$6+Returns!$C$9)/(($B12*Inputs!$C$21)*(1+Inputs!$C$27)+Inputs!$C$23+Inputs!$C$40*Inputs!$C$25+Inputs!$C$41*Inputs!$C$26-Inputs!$C$40-(Inputs!$C$22-Inputs!$C$24)))^(1/Returns!$C$12)-1 -> 0.018858089 | E12: =((Returns!$C$6*E$6+Returns!$C$9)/(($B12*Inputs!$C$21)*(1+Inputs!$C$27)+Inputs!$C$23+Inputs!$C$40*Inputs!$C$25+Inputs!$C$41*Inputs!$C$26-Inputs!$C$40-(Inputs!$C$22-Inputs!$C$24)))^(1/Returns!$C$12)-1 -> 0.052732552 | F12: =((Returns!$C$6*F$6+Returns!$C$9)/(($B12*Inputs!$C$21)*(1+Inputs!$C$27)+Inputs!$C$23+Inputs!$C$40*Inputs!$C$25+Inputs!$C$41*Inputs!$C$26-Inputs!$C$40-(Inputs!$C$22-Inputs!$C$24)))^(1/Returns!$C$12)-1 -> 0.08273633 | G12: =((Returns!$C$6*G$6+Returns!$C$9)/(($B12*Inputs!$C$21)*(1+Inputs!$C$27)+Inputs!$C$23+Inputs!$C$40*Inputs!$C$25+Inputs!$C$41*Inputs!$C$26-Inputs!$C$40-(Inputs!$C$22-Inputs!$C$24)))^(1/Returns!$C$12)-1 -> 0.10974155 | H12: =((Returns!$C$6*H$6+Returns!$C$9)/(($B12*Inputs!$C$21)*(1+Inputs!$C$27)+Inputs!$C$23+Inputs!$C$40*Inputs!$C$25+Inputs!$C$41*Inputs!$C$26-Inputs!$C$40-(Inputs!$C$22-Inputs!$C$24)))^(1/Returns!$C$12)-1 -> 0.13434834
B14: Dark cells: IRR at or above the 20% target
